2024-01-31 15:44:29,771 | INFO | utils.utils | 


Starting main program...
2024-01-31 15:44:29,771 | DEBUG | utils.utils | Beginning to clear recordings from directory: backend\data\original
2024-01-31 15:44:29,772 | ERROR | __main__ | Unexpected error: [WinError 3] The system cannot find the path specified: 'backend\\data\\original'
Traceback (most recent call last):
  File "C:\Users\hello\coding\full_stack_apps\advanced_ai_call_assistant\backend\main.py", line 69, in <module>
    setup_recording_environment(ORIGINAL_RECORDINGS_DIR)
  File "C:\Users\hello\coding\full_stack_apps\advanced_ai_call_assistant\backend\utils\utils.py", line 104, in setup_recording_environment
    for filename in os.listdir(directory):
FileNotFoundError: [WinError 3] The system cannot find the path specified: 'backend\\data\\original'
2024-01-31 15:48:53,625 | INFO | utils.utils | 


Starting main program...
2024-01-31 15:48:53,626 | DEBUG | utils.utils | Beginning to clear recordings from directory: backend\data\recordings
2024-01-31 15:48:53,626 | INFO | utils.utils | There were no files to delete from 'backend\data\recordings' directory.
2024-01-31 15:48:53,642 | DEBUG | root | Audio Stream Processor initialized | Sample Rate: 32000, Chunk Duration = 0.5 seconds
2024-01-31 15:48:53,643 | DEBUG | recorder.audio_buffer | AudioBuffer initialized with buffer duration: 40 secs, sample rate: 32000
2024-01-31 15:48:53,643 | INFO | recorder.audio_segment_manager | Audio segment manager initialized.
2024-01-31 15:48:53,696 | INFO | recorder.audio_capture_processor | Audio stream opened successfully. Recording started.
2024-01-31 15:48:58,157 | DEBUG | asyncio | Using proactor: IocpProactor
2024-01-31 15:49:22,738 | INFO | recorder.audio_segment_manager | Speech detected for the first time.
2024-01-31 15:49:35,720 | DEBUG | recorder.audio_segment_manager | Speech end detected | Time: 2024-01-31 15:49:35.719932
2024-01-31 15:49:35,733 | INFO | recorder.audio_segment_manager | Buffer saved for transcription: backend\data\recordings\2024-01-31_15-49-35.wav
2024-01-31 15:49:35,733 | INFO | recorder.audio_segment_manager | Buffer sent for transcription | Buffer Length: 12.0 seconds
2024-01-31 15:49:35,734 | DEBUG | recorder.audio_buffer | Clearing audio buffer
2024-01-31 15:49:40,570 | ERROR | __mp_main__ | Error occurred in transcription worker: [WinError 6] The handle is invalid
Traceback (most recent call last):
  File "C:\Users\hello\coding\full_stack_apps\advanced_ai_call_assistant\backend\main.py", line 24, in transcription_worker
    transcriber.load_model()
  File "C:\Users\hello\coding\full_stack_apps\advanced_ai_call_assistant\backend\transcriber\transcriber_service.py", line 36, in load_model
    self.whisper_model = WhisperModelLoader.load_model(MODEL_NAME)
  File "C:\Users\hello\coding\full_stack_apps\advanced_ai_call_assistant\backend\utils\load_model.py", line 18, in load_model
    whisper_model = whisper.load_model("base")
  File "c:\Users\hello\coding\python\virtual_environments\python399_venv\lib\site-packages\whisper\__init__.py", line 133, in load_model
    checkpoint_file = _download(_MODELS[name], download_root, in_memory)
  File "c:\Users\hello\coding\python\virtual_environments\python399_venv\lib\site-packages\whisper\__init__.py", line 70, in _download
    with tqdm(
  File "c:\Users\hello\coding\python\virtual_environments\python399_venv\lib\site-packages\tqdm\std.py", line 1099, in __init__
    self.refresh(lock_args=self.lock_args)
  File "c:\Users\hello\coding\python\virtual_environments\python399_venv\lib\site-packages\tqdm\std.py", line 1348, in refresh
    self.display()
  File "c:\Users\hello\coding\python\virtual_environments\python399_venv\lib\site-packages\tqdm\std.py", line 1496, in display
    self.sp(self.__str__() if msg is None else msg)
  File "c:\Users\hello\coding\python\virtual_environments\python399_venv\lib\site-packages\tqdm\std.py", line 462, in print_status
    fp_write('\r' + s + (' ' * max(last_len[0] - len_s, 0)))
  File "c:\Users\hello\coding\python\virtual_environments\python399_venv\lib\site-packages\tqdm\std.py", line 455, in fp_write
    fp.write(str(s))
  File "c:\Users\hello\coding\python\virtual_environments\python399_venv\lib\site-packages\tqdm\utils.py", line 195, in inner
    return func(*args, **kwargs)
  File "c:\Users\hello\.vscode\extensions\ms-python.python-2023.22.1\pythonFiles\lib\python\debugpy\_vendored\pydevd\_pydevd_bundle\pydevd_io.py", line 40, in write
    r.write(s)
OSError: [WinError 6] The handle is invalid
2024-01-31 15:57:01,602 | INFO | utils.utils | 


Starting main program...
2024-01-31 15:57:01,603 | DEBUG | utils.utils | Beginning to clear recordings from directory: backend\data\recordings
2024-01-31 15:57:01,603 | DEBUG | utils.utils | Processing file: backend\data\recordings\2024-01-31_15-49-35.wav
2024-01-31 15:57:01,604 | DEBUG | utils.utils | Deleted file: backend\data\recordings\2024-01-31_15-49-35.wav
2024-01-31 15:57:01,604 | INFO | utils.utils | Finished clearing recordings. 1 files deleted.
2024-01-31 15:57:01,607 | DEBUG | root | Audio Stream Processor initialized | Sample Rate: 32000, Chunk Duration = 0.5 seconds
2024-01-31 15:57:01,607 | DEBUG | recorder.audio_buffer | AudioBuffer initialized with buffer duration: 40 secs, sample rate: 32000
2024-01-31 15:57:01,607 | INFO | recorder.audio_segment_manager | Audio segment manager initialized.
2024-01-31 15:57:01,610 | DEBUG | asyncio | Using proactor: IocpProactor
2024-01-31 15:57:01,629 | INFO | recorder.audio_capture_processor | Audio stream opened successfully. Recording started.
2024-01-31 15:57:15,161 | INFO | recorder.audio_segment_manager | Speech detected for the first time.
2024-01-31 15:57:19,170 | DEBUG | recorder.audio_segment_manager | Speech end detected | Time: 2024-01-31 15:57:19.170732
2024-01-31 15:57:19,177 | INFO | recorder.audio_segment_manager | Buffer saved for transcription: backend\data\recordings\2024-01-31_15-57-19.wav
2024-01-31 15:57:19,177 | INFO | recorder.audio_segment_manager | Buffer sent for transcription | Buffer Length: 2.5 seconds
2024-01-31 15:57:19,178 | DEBUG | recorder.audio_buffer | Clearing audio buffer
2024-01-31 15:57:21,151 | INFO | recorder.audio_segment_manager | Speech detected for the first time.
2024-01-31 15:57:25,670 | DEBUG | recorder.audio_segment_manager | Speech end detected | Time: 2024-01-31 15:57:25.670795
2024-01-31 15:57:25,673 | INFO | recorder.audio_segment_manager | Buffer saved for transcription: backend\data\recordings\2024-01-31_15-57-25.wav
2024-01-31 15:57:25,674 | INFO | recorder.audio_segment_manager | Buffer sent for transcription | Buffer Length: 4.0 seconds
2024-01-31 15:57:25,674 | DEBUG | recorder.audio_buffer | Clearing audio buffer
2024-01-31 15:57:44,030 | ERROR | __main__ | Error occurred in transcription worker: [WinError 6] The handle is invalid
Traceback (most recent call last):
  File "C:\Users\hello\coding\full_stack_apps\advanced_ai_call_assistant\backend\main.py", line 25, in transcription_worker
    transcriber.load_model()
  File "C:\Users\hello\coding\full_stack_apps\advanced_ai_call_assistant\backend\transcriber\transcriber_service.py", line 36, in load_model
    self.whisper_model = WhisperModelLoader.load_model(MODEL_NAME)
  File "C:\Users\hello\coding\full_stack_apps\advanced_ai_call_assistant\backend\utils\load_model.py", line 18, in load_model
    whisper_model = whisper.load_model("base")
  File "c:\Users\hello\coding\python\virtual_environments\python399_venv\lib\site-packages\whisper\__init__.py", line 133, in load_model
    checkpoint_file = _download(_MODELS[name], download_root, in_memory)
  File "c:\Users\hello\coding\python\virtual_environments\python399_venv\lib\site-packages\whisper\__init__.py", line 70, in _download
    with tqdm(
  File "c:\Users\hello\coding\python\virtual_environments\python399_venv\lib\site-packages\tqdm\std.py", line 1099, in __init__
    self.refresh(lock_args=self.lock_args)
  File "c:\Users\hello\coding\python\virtual_environments\python399_venv\lib\site-packages\tqdm\std.py", line 1348, in refresh
    self.display()
  File "c:\Users\hello\coding\python\virtual_environments\python399_venv\lib\site-packages\tqdm\std.py", line 1496, in display
    self.sp(self.__str__() if msg is None else msg)
  File "c:\Users\hello\coding\python\virtual_environments\python399_venv\lib\site-packages\tqdm\std.py", line 462, in print_status
    fp_write('\r' + s + (' ' * max(last_len[0] - len_s, 0)))
  File "c:\Users\hello\coding\python\virtual_environments\python399_venv\lib\site-packages\tqdm\std.py", line 455, in fp_write
    fp.write(str(s))
  File "c:\Users\hello\coding\python\virtual_environments\python399_venv\lib\site-packages\tqdm\utils.py", line 195, in inner
    return func(*args, **kwargs)
OSError: [WinError 6] The handle is invalid
2024-01-31 16:01:46,182 | INFO | utils.utils | 


Starting main program...
2024-01-31 16:01:46,182 | DEBUG | utils.utils | Beginning to clear recordings from directory: backend\data\recordings
2024-01-31 16:01:46,182 | DEBUG | utils.utils | Processing file: backend\data\recordings\2024-01-31_15-57-19.wav
2024-01-31 16:01:46,182 | DEBUG | utils.utils | Deleted file: backend\data\recordings\2024-01-31_15-57-19.wav
2024-01-31 16:01:46,182 | DEBUG | utils.utils | Processing file: backend\data\recordings\2024-01-31_15-57-25.wav
2024-01-31 16:01:46,183 | DEBUG | utils.utils | Deleted file: backend\data\recordings\2024-01-31_15-57-25.wav
2024-01-31 16:01:46,183 | INFO | utils.utils | Finished clearing recordings. 2 files deleted.
2024-01-31 16:01:46,185 | DEBUG | root | Audio Stream Processor initialized | Sample Rate: 32000, Chunk Duration = 0.5 seconds
2024-01-31 16:01:46,185 | DEBUG | recorder.audio_buffer | AudioBuffer initialized with buffer duration: 40 secs, sample rate: 32000
2024-01-31 16:01:46,185 | INFO | recorder.audio_segment_manager | Audio segment manager initialized.
2024-01-31 16:01:46,198 | INFO | recorder.audio_capture_processor | Audio stream opened successfully. Recording started.
2024-01-31 16:01:48,703 | DEBUG | asyncio | Using proactor: IocpProactor
2024-01-31 16:02:14,728 | INFO | recorder.audio_segment_manager | Speech detected for the first time.
2024-01-31 16:02:27,719 | DEBUG | recorder.audio_segment_manager | Speech end detected | Time: 2024-01-31 16:02:27.719277
2024-01-31 16:02:27,727 | INFO | recorder.audio_segment_manager | Buffer saved for transcription: backend\data\recordings\2024-01-31_16-02-27.wav
2024-01-31 16:02:27,727 | INFO | recorder.audio_segment_manager | Buffer sent for transcription | Buffer Length: 12.5 seconds
2024-01-31 16:02:27,727 | DEBUG | recorder.audio_buffer | Clearing audio buffer
2024-01-31 16:02:32,098 | ERROR | __mp_main__ | Error occurred in transcription worker: [WinError 6] The handle is invalid
Traceback (most recent call last):
  File "C:\Users\hello\coding\full_stack_apps\advanced_ai_call_assistant\backend\main.py", line 25, in transcription_worker
    transcriber.load_model()
  File "C:\Users\hello\coding\full_stack_apps\advanced_ai_call_assistant\backend\transcriber\transcriber_service.py", line 36, in load_model
    self.whisper_model = WhisperModelLoader.load_model(MODEL_NAME)
  File "C:\Users\hello\coding\full_stack_apps\advanced_ai_call_assistant\backend\utils\load_model.py", line 18, in load_model
    whisper_model = whisper.load_model("base")
  File "C:\Users\hello\coding\python\virtual_environments\python399_venv\lib\site-packages\whisper\__init__.py", line 133, in load_model
    checkpoint_file = _download(_MODELS[name], download_root, in_memory)
  File "C:\Users\hello\coding\python\virtual_environments\python399_venv\lib\site-packages\whisper\__init__.py", line 70, in _download
    with tqdm(
  File "C:\Users\hello\coding\python\virtual_environments\python399_venv\lib\site-packages\tqdm\std.py", line 1097, in __init__
    self.sp = self.status_printer(self.fp)
  File "C:\Users\hello\coding\python\virtual_environments\python399_venv\lib\site-packages\tqdm\std.py", line 451, in status_printer
    getattr(sys.stderr, 'flush', lambda: None)()
OSError: [WinError 6] The handle is invalid
2024-01-31 16:10:39,718 | INFO | recorder.audio_segment_manager | Speech detected for the first time.
2024-01-31 16:10:42,208 | DEBUG | recorder.audio_segment_manager | Speech end detected | Time: 2024-01-31 16:10:42.208743
2024-01-31 16:10:42,210 | INFO | recorder.audio_segment_manager | Buffer saved for transcription: backend\data\recordings\2024-01-31_16-10-42.wav
2024-01-31 16:10:42,210 | INFO | recorder.audio_segment_manager | Buffer sent for transcription | Buffer Length: 2.0 seconds
2024-01-31 16:10:42,210 | DEBUG | recorder.audio_buffer | Clearing audio buffer
2024-01-31 22:44:16,120 | INFO | utils.utils | 


Starting main program...
2024-01-31 22:44:16,120 | DEBUG | utils.utils | Beginning to clear recordings from directory: backend\data\recordings
2024-01-31 22:44:16,120 | DEBUG | utils.utils | Processing file: backend\data\recordings\2024-01-31_16-02-27.wav
2024-01-31 22:44:16,120 | DEBUG | utils.utils | Deleted file: backend\data\recordings\2024-01-31_16-02-27.wav
2024-01-31 22:44:16,120 | DEBUG | utils.utils | Processing file: backend\data\recordings\2024-01-31_16-10-42.wav
2024-01-31 22:44:16,120 | DEBUG | utils.utils | Deleted file: backend\data\recordings\2024-01-31_16-10-42.wav
2024-01-31 22:44:16,120 | INFO | utils.utils | Finished clearing recordings. 2 files deleted.
2024-01-31 22:44:16,120 | DEBUG | root | Audio Stream Processor initialized | Sample Rate: 32000, Chunk Duration = 0.5 seconds
2024-01-31 22:44:16,120 | DEBUG | recorder.audio_buffer | AudioBuffer initialized with buffer duration: 40 secs, sample rate: 32000
2024-01-31 22:44:16,120 | INFO | recorder.audio_segment_manager | Audio segment manager initialized.
2024-01-31 22:44:16,182 | INFO | recorder.audio_capture_processor | Audio stream opened successfully. Recording started.
2024-01-31 22:44:20,113 | DEBUG | asyncio | Using proactor: IocpProactor
2024-01-31 22:44:21,339 | INFO | utils.load_model | CUDA not available, loaded Whisper model onto CPU.
2024-01-31 22:44:53,225 | INFO | recorder.audio_segment_manager | Speech detected for the first time.
2024-01-31 22:45:19,225 | DEBUG | recorder.audio_segment_manager | Speech end detected | Time: 2024-01-31 22:45:19.225534
2024-01-31 22:45:19,275 | INFO | recorder.audio_segment_manager | Buffer saved for transcription: backend\data\recordings\2024-01-31_22-45-19.wav
2024-01-31 22:45:19,275 | INFO | recorder.audio_segment_manager | Buffer sent for transcription | Buffer Length: 24.0 seconds
2024-01-31 22:45:19,275 | DEBUG | recorder.audio_buffer | Clearing audio buffer
2024-01-31 22:45:24,340 | DEBUG | transcriber.transcriber_service | Transcription Complete | Time: 2024-01-31 22:45:24.340360
2024-01-31 22:45:24,340 | INFO | transcriber.transcriber_service | Speech End Time: 2024-01-31 22:45:19.225534
2024-01-31 22:45:24,340 | INFO | transcriber.transcriber_service | Transcription time: 5.11 seconds
2024-01-31 22:45:24,340 | INFO | transcriber.transcriber_service | Transcription: Take a look at our cities. Their Helen immigration is the reason. The city of Chicago was in tough shape even before Joe Biden opened the border. Now, parts of it are basically uninhabitable. Even the socialist mayor of Chicago says the city is breaking under the strain. Without real significant investment from our federal government, it won't just be the city.
2024-01-31 22:45:24,353 | DEBUG | urllib3.connectionpool | Starting new HTTP connection (1): localhost:3000
2024-01-31 22:45:28,409 | ERROR | transcriber.transcriber_service | Error sending data to Next.js: HTTPConnectionPool(host='localhost', port=3000): Max retries exceeded with url: /api/subscribe (Caused by NewConnectionError('<urllib3.connection.HTTPConnection object at 0x00000267727E4DF0>: Failed to establish a new connection: [WinError 10061] No connection could be made because the target machine actively refused it'))
Traceback (most recent call last):
  File "C:\Users\markb\miniconda3\envs\advanced_ai_call_assistant\lib\site-packages\urllib3\connection.py", line 198, in _new_conn
    sock = connection.create_connection(
  File "C:\Users\markb\miniconda3\envs\advanced_ai_call_assistant\lib\site-packages\urllib3\util\connection.py", line 85, in create_connection
    raise err
  File "C:\Users\markb\miniconda3\envs\advanced_ai_call_assistant\lib\site-packages\urllib3\util\connection.py", line 73, in create_connection
    sock.connect(sa)
ConnectionRefusedError: [WinError 10061] No connection could be made because the target machine actively refused it

The above exception was the direct cause of the following exception:

Traceback (most recent call last):
  File "C:\Users\markb\miniconda3\envs\advanced_ai_call_assistant\lib\site-packages\urllib3\connectionpool.py", line 793, in urlopen
    response = self._make_request(
  File "C:\Users\markb\miniconda3\envs\advanced_ai_call_assistant\lib\site-packages\urllib3\connectionpool.py", line 496, in _make_request
    conn.request(
  File "C:\Users\markb\miniconda3\envs\advanced_ai_call_assistant\lib\site-packages\urllib3\connection.py", line 400, in request
    self.endheaders()
  File "C:\Users\markb\miniconda3\envs\advanced_ai_call_assistant\lib\http\client.py", line 1280, in endheaders
    self._send_output(message_body, encode_chunked=encode_chunked)
  File "C:\Users\markb\miniconda3\envs\advanced_ai_call_assistant\lib\http\client.py", line 1040, in _send_output
    self.send(msg)
  File "C:\Users\markb\miniconda3\envs\advanced_ai_call_assistant\lib\http\client.py", line 980, in send
    self.connect()
  File "C:\Users\markb\miniconda3\envs\advanced_ai_call_assistant\lib\site-packages\urllib3\connection.py", line 238, in connect
    self.sock = self._new_conn()
  File "C:\Users\markb\miniconda3\envs\advanced_ai_call_assistant\lib\site-packages\urllib3\connection.py", line 213, in _new_conn
    raise NewConnectionError(
urllib3.exceptions.NewConnectionError: <urllib3.connection.HTTPConnection object at 0x00000267727E4DF0>: Failed to establish a new connection: [WinError 10061] No connection could be made because the target machine actively refused it

The above exception was the direct cause of the following exception:

Traceback (most recent call last):
  File "C:\Users\markb\miniconda3\envs\advanced_ai_call_assistant\lib\site-packages\requests\adapters.py", line 486, in send
    resp = conn.urlopen(
  File "C:\Users\markb\miniconda3\envs\advanced_ai_call_assistant\lib\site-packages\urllib3\connectionpool.py", line 847, in urlopen
    retries = retries.increment(
  File "C:\Users\markb\miniconda3\envs\advanced_ai_call_assistant\lib\site-packages\urllib3\util\retry.py", line 515, in increment
    raise MaxRetryError(_pool, url, reason) from reason  # type: ignore[arg-type]
urllib3.exceptions.MaxRetryError: HTTPConnectionPool(host='localhost', port=3000): Max retries exceeded with url: /api/subscribe (Caused by NewConnectionError('<urllib3.connection.HTTPConnection object at 0x00000267727E4DF0>: Failed to establish a new connection: [WinError 10061] No connection could be made because the target machine actively refused it'))

During handling of the above exception, another exception occurred:

Traceback (most recent call last):
  File "C:\Users\markb\coding\full_stack_apps\advanced_ai_call_assistant\backend\transcriber\transcriber_service.py", line 26, in send_data_to_nextjs
    response = requests.post(url, json=data)
  File "C:\Users\markb\miniconda3\envs\advanced_ai_call_assistant\lib\site-packages\requests\api.py", line 115, in post
    return request("post", url, data=data, json=json, **kwargs)
  File "C:\Users\markb\miniconda3\envs\advanced_ai_call_assistant\lib\site-packages\requests\api.py", line 59, in request
    return session.request(method=method, url=url, **kwargs)
  File "C:\Users\markb\miniconda3\envs\advanced_ai_call_assistant\lib\site-packages\requests\sessions.py", line 589, in request
    resp = self.send(prep, **send_kwargs)
  File "C:\Users\markb\miniconda3\envs\advanced_ai_call_assistant\lib\site-packages\requests\sessions.py", line 703, in send
    r = adapter.send(request, **kwargs)
  File "C:\Users\markb\miniconda3\envs\advanced_ai_call_assistant\lib\site-packages\requests\adapters.py", line 519, in send
    raise ConnectionError(e, request=request)
requests.exceptions.ConnectionError: HTTPConnectionPool(host='localhost', port=3000): Max retries exceeded with url: /api/subscribe (Caused by NewConnectionError('<urllib3.connection.HTTPConnection object at 0x00000267727E4DF0>: Failed to establish a new connection: [WinError 10061] No connection could be made because the target machine actively refused it'))
2024-02-01 07:28:32,005 | INFO | utils.utils | 


Starting main program...
2024-02-01 07:28:32,005 | DEBUG | utils.utils | Beginning to clear recordings from directory: backend\data\recordings
2024-02-01 07:28:32,006 | DEBUG | utils.utils | Processing file: backend\data\recordings\2024-01-31_22-45-19.wav
2024-02-01 07:28:32,006 | DEBUG | utils.utils | Deleted file: backend\data\recordings\2024-01-31_22-45-19.wav
2024-02-01 07:28:32,006 | INFO | utils.utils | Finished clearing recordings. 1 files deleted.
2024-02-01 07:28:32,017 | DEBUG | root | Audio Stream Processor initialized | Sample Rate: 32000, Chunk Duration = 0.5 seconds
2024-02-01 07:28:32,017 | DEBUG | recorder.audio_buffer | AudioBuffer initialized with buffer duration: 40 secs, sample rate: 32000
2024-02-01 07:28:32,018 | INFO | recorder.audio_segment_manager | Audio segment manager initialized.
2024-02-01 07:28:32,059 | INFO | recorder.audio_capture_processor | Audio stream opened successfully. Recording started.
2024-02-01 07:28:32,607 | INFO | recorder.audio_segment_manager | Speech detected for the first time.
2024-02-01 07:28:34,075 | DEBUG | recorder.audio_segment_manager | Speech end detected | Time: 2024-02-01 07:28:34.075932
2024-02-01 07:28:34,087 | INFO | recorder.audio_segment_manager | Buffer saved for transcription: backend\data\recordings\2024-02-01_07-28-34.wav
2024-02-01 07:28:34,087 | INFO | recorder.audio_segment_manager | Buffer sent for transcription | Buffer Length: 0.5 seconds
2024-02-01 07:28:34,089 | DEBUG | recorder.audio_buffer | Clearing audio buffer
2024-02-01 07:28:36,779 | DEBUG | asyncio | Using proactor: IocpProactor
2024-02-01 07:28:38,009 | INFO | utils.load_model | CUDA not available, loaded Whisper model onto CPU.
2024-02-01 07:28:40,322 | DEBUG | transcriber.transcriber_service | Transcription Complete | Time: 2024-02-01 07:28:40.322331
2024-02-01 07:28:40,322 | INFO | transcriber.transcriber_service | Speech End Time: 2024-02-01 07:28:34.075932
2024-02-01 07:28:40,323 | INFO | transcriber.transcriber_service | Transcription time: 6.25 seconds
2024-02-01 07:28:40,323 | WARNING | transcriber.transcriber_service | No speech detected or skipping the recording.
2024-02-01 07:29:11,605 | INFO | recorder.audio_segment_manager | Speech detected for the first time.
2024-02-01 07:29:13,085 | DEBUG | recorder.audio_segment_manager | Speech end detected | Time: 2024-02-01 07:29:13.085362
2024-02-01 07:29:13,087 | INFO | recorder.audio_segment_manager | Buffer saved for transcription: backend\data\recordings\2024-02-01_07-29-13.wav
2024-02-01 07:29:13,087 | INFO | recorder.audio_segment_manager | Buffer sent for transcription | Buffer Length: 0.5 seconds
2024-02-01 07:29:13,087 | DEBUG | recorder.audio_buffer | Clearing audio buffer
2024-02-01 07:29:14,728 | DEBUG | transcriber.transcriber_service | Transcription Complete | Time: 2024-02-01 07:29:14.728062
2024-02-01 07:29:14,728 | INFO | transcriber.transcriber_service | Speech End Time: 2024-02-01 07:29:13.085362
2024-02-01 07:29:14,729 | INFO | transcriber.transcriber_service | Transcription time: 1.64 seconds
2024-02-01 07:29:14,729 | WARNING | transcriber.transcriber_service | No speech detected or skipping the recording.
2024-02-01 07:29:20,105 | INFO | recorder.audio_segment_manager | Speech detected for the first time.
2024-02-01 07:29:39,595 | DEBUG | recorder.audio_segment_manager | Speech end detected | Time: 2024-02-01 07:29:39.595239
2024-02-01 07:29:39,609 | INFO | recorder.audio_segment_manager | Buffer saved for transcription: backend\data\recordings\2024-02-01_07-29-39.wav
2024-02-01 07:29:39,610 | INFO | recorder.audio_segment_manager | Buffer sent for transcription | Buffer Length: 19.0 seconds
2024-02-01 07:29:39,610 | DEBUG | recorder.audio_buffer | Clearing audio buffer
2024-02-01 07:29:44,487 | DEBUG | transcriber.transcriber_service | Transcription Complete | Time: 2024-02-01 07:29:44.487832
2024-02-01 07:29:44,487 | INFO | transcriber.transcriber_service | Speech End Time: 2024-02-01 07:29:39.595239
2024-02-01 07:29:44,487 | INFO | transcriber.transcriber_service | Transcription time: 4.89 seconds
2024-02-01 07:29:44,487 | INFO | transcriber.transcriber_service | Transcription: But it even under welcome to Piers Morgana's sense. Ben Shapiro is one of the most talked about political pundits on the planet. When he sounds off, people listen. And as of this week, they've been listening to him rapping. Yes, you heard that correctly. The man he once informously said, fact, rap is a music. And if you think it is your stupid, sparking international.
2024-02-01 07:29:44,500 | DEBUG | urllib3.connectionpool | Starting new HTTP connection (1): localhost:3000
2024-02-01 07:29:53,563 | DEBUG | urllib3.connectionpool | http://localhost:3000 "POST /api/subscribe HTTP/1.1" 404 None
2024-02-01 07:29:53,810 | ERROR | transcriber.transcriber_service | Error sending data to Next.js: Expecting value: line 1 column 1 (char 0)
Traceback (most recent call last):
  File "C:\Users\markb\miniconda3\envs\advanced_ai_call_assistant\lib\site-packages\requests\models.py", line 971, in json
    return complexjson.loads(self.text, **kwargs)
  File "C:\Users\markb\miniconda3\envs\advanced_ai_call_assistant\lib\json\__init__.py", line 346, in loads
    return _default_decoder.decode(s)
  File "C:\Users\markb\miniconda3\envs\advanced_ai_call_assistant\lib\json\decoder.py", line 337, in decode
    obj, end = self.raw_decode(s, idx=_w(s, 0).end())
  File "C:\Users\markb\miniconda3\envs\advanced_ai_call_assistant\lib\json\decoder.py", line 355, in raw_decode
    raise JSONDecodeError("Expecting value", s, err.value) from None
json.decoder.JSONDecodeError: Expecting value: line 1 column 1 (char 0)

During handling of the above exception, another exception occurred:

Traceback (most recent call last):
  File "C:\Users\markb\coding\full_stack_apps\advanced_ai_call_assistant\backend\transcriber\transcriber_service.py", line 28, in send_data_to_nextjs
    f"Data sent to Next.js | Status Code: {response.status_code} | Response: {response.json()}"
  File "C:\Users\markb\miniconda3\envs\advanced_ai_call_assistant\lib\site-packages\requests\models.py", line 975, in json
    raise RequestsJSONDecodeError(e.msg, e.doc, e.pos)
requests.exceptions.JSONDecodeError: Expecting value: line 1 column 1 (char 0)
2024-02-01 07:31:07,016 | INFO | utils.utils | 


Starting main program...
2024-02-01 07:31:07,017 | DEBUG | utils.utils | Beginning to clear recordings from directory: backend\data\recordings
2024-02-01 07:31:07,017 | DEBUG | utils.utils | Processing file: backend\data\recordings\2024-02-01_07-28-34.wav
2024-02-01 07:31:07,018 | DEBUG | utils.utils | Deleted file: backend\data\recordings\2024-02-01_07-28-34.wav
2024-02-01 07:31:07,018 | DEBUG | utils.utils | Processing file: backend\data\recordings\2024-02-01_07-29-13.wav
2024-02-01 07:31:07,018 | DEBUG | utils.utils | Deleted file: backend\data\recordings\2024-02-01_07-29-13.wav
2024-02-01 07:31:07,018 | DEBUG | utils.utils | Processing file: backend\data\recordings\2024-02-01_07-29-39.wav
2024-02-01 07:31:07,019 | DEBUG | utils.utils | Deleted file: backend\data\recordings\2024-02-01_07-29-39.wav
2024-02-01 07:31:07,019 | INFO | utils.utils | Finished clearing recordings. 3 files deleted.
2024-02-01 07:31:07,027 | DEBUG | root | Audio Stream Processor initialized | Sample Rate: 32000, Chunk Duration = 0.5 seconds
2024-02-01 07:31:07,027 | DEBUG | recorder.audio_buffer | AudioBuffer initialized with buffer duration: 40 secs, sample rate: 32000
2024-02-01 07:31:07,027 | INFO | recorder.audio_segment_manager | Audio segment manager initialized.
2024-02-01 07:31:07,057 | INFO | recorder.audio_capture_processor | Audio stream opened successfully. Recording started.
2024-02-01 07:31:11,477 | DEBUG | asyncio | Using proactor: IocpProactor
2024-02-01 07:31:12,836 | INFO | utils.load_model | CUDA not available, loaded Whisper model onto CPU.
2024-02-01 07:31:19,579 | INFO | recorder.audio_segment_manager | Speech detected for the first time.
2024-02-01 07:31:34,591 | DEBUG | recorder.audio_segment_manager | Speech end detected | Time: 2024-02-01 07:31:34.591625
2024-02-01 07:31:34,648 | INFO | recorder.audio_segment_manager | Buffer saved for transcription: backend\data\recordings\2024-02-01_07-31-34.wav
2024-02-01 07:31:34,649 | INFO | recorder.audio_segment_manager | Buffer sent for transcription | Buffer Length: 14.0 seconds
2024-02-01 07:31:34,651 | DEBUG | recorder.audio_buffer | Clearing audio buffer
2024-02-01 07:31:38,461 | DEBUG | transcriber.transcriber_service | Transcription Complete | Time: 2024-02-01 07:31:38.461653
2024-02-01 07:31:38,461 | INFO | transcriber.transcriber_service | Speech End Time: 2024-02-01 07:31:34.591625
2024-02-01 07:31:38,461 | INFO | transcriber.transcriber_service | Transcription time: 3.87 seconds
2024-02-01 07:31:38,461 | INFO | transcriber.transcriber_service | Transcription: currently has, this is true, the number one hip-hop single in the United States will find out why and frankly how a little later when he's not dropping the rat beat Ben Shapiro's day job is dropping hard truths, at least that's
2024-02-01 07:31:38,479 | DEBUG | urllib3.connectionpool | Starting new HTTP connection (1): localhost:3000
2024-02-01 07:31:38,903 | DEBUG | urllib3.connectionpool | http://localhost:3000 "POST /api/receive-data HTTP/1.1" 200 None
2024-02-01 07:31:38,905 | INFO | transcriber.transcriber_service | Data sent to Next.js | Status Code: 200 | Response: {'message': 'Data received successfully'}
2024-02-01 09:57:03,588 | INFO | utils.utils | 


Starting main program...
2024-02-01 09:57:03,589 | DEBUG | utils.utils | Beginning to clear recordings from directory: backend\data\recordings
2024-02-01 09:57:03,589 | DEBUG | utils.utils | Processing file: backend\data\recordings\2024-02-01_07-31-34.wav
2024-02-01 09:57:03,590 | DEBUG | utils.utils | Deleted file: backend\data\recordings\2024-02-01_07-31-34.wav
2024-02-01 09:57:03,590 | INFO | utils.utils | Finished clearing recordings. 1 files deleted.
2024-02-01 09:57:03,601 | DEBUG | root | Audio Stream Processor initialized | Sample Rate: 32000, Chunk Duration = 0.5 seconds
2024-02-01 09:57:03,602 | DEBUG | recorder.audio_buffer | AudioBuffer initialized with buffer duration: 40 secs, sample rate: 32000
2024-02-01 09:57:03,602 | INFO | recorder.audio_segment_manager | Audio segment manager initialized.
2024-02-01 09:57:03,617 | INFO | recorder.audio_capture_processor | Audio stream opened successfully. Recording started.
2024-02-01 09:57:08,337 | DEBUG | asyncio | Using proactor: IocpProactor
2024-02-01 09:57:50,791 | ERROR | __mp_main__ | Error occurred in transcription worker: [WinError 6] The handle is invalid
Traceback (most recent call last):
  File "C:\Users\hello\coding\full_stack_apps\advanced_ai_call_assistant\backend\main.py", line 25, in transcription_worker
    transcriber.load_model()
  File "C:\Users\hello\coding\full_stack_apps\advanced_ai_call_assistant\backend\transcriber\transcriber_service.py", line 37, in load_model
    self.whisper_model = WhisperModelLoader.load_model(MODEL_NAME)
  File "C:\Users\hello\coding\full_stack_apps\advanced_ai_call_assistant\backend\utils\load_model.py", line 18, in load_model
    whisper_model = whisper.load_model("base")
  File "C:\Users\hello\coding\python\virtual_environments\python399_venv\lib\site-packages\whisper\__init__.py", line 133, in load_model
    checkpoint_file = _download(_MODELS[name], download_root, in_memory)
  File "C:\Users\hello\coding\python\virtual_environments\python399_venv\lib\site-packages\whisper\__init__.py", line 70, in _download
    with tqdm(
  File "C:\Users\hello\coding\python\virtual_environments\python399_venv\lib\site-packages\tqdm\std.py", line 1099, in __init__
    self.refresh(lock_args=self.lock_args)
  File "C:\Users\hello\coding\python\virtual_environments\python399_venv\lib\site-packages\tqdm\std.py", line 1348, in refresh
    self.display()
  File "C:\Users\hello\coding\python\virtual_environments\python399_venv\lib\site-packages\tqdm\std.py", line 1496, in display
    self.sp(self.__str__() if msg is None else msg)
  File "C:\Users\hello\coding\python\virtual_environments\python399_venv\lib\site-packages\tqdm\std.py", line 462, in print_status
    fp_write('\r' + s + (' ' * max(last_len[0] - len_s, 0)))
  File "C:\Users\hello\coding\python\virtual_environments\python399_venv\lib\site-packages\tqdm\std.py", line 455, in fp_write
    fp.write(str(s))
  File "C:\Users\hello\coding\python\virtual_environments\python399_venv\lib\site-packages\tqdm\utils.py", line 195, in inner
    return func(*args, **kwargs)
  File "c:\Users\hello\.vscode\extensions\ms-python.python-2023.22.1\pythonFiles\lib\python\debugpy\_vendored\pydevd\_pydevd_bundle\pydevd_io.py", line 40, in write
    r.write(s)
OSError: [WinError 6] The handle is invalid
2024-02-01 09:58:48,645 | INFO | utils.utils | 


Starting main program...
2024-02-01 09:58:48,646 | DEBUG | utils.utils | Beginning to clear recordings from directory: backend\data\recordings
2024-02-01 09:58:48,646 | INFO | utils.utils | There were no files to delete from 'backend\data\recordings' directory.
2024-02-01 09:58:48,653 | DEBUG | root | Audio Stream Processor initialized | Sample Rate: 32000, Chunk Duration = 0.5 seconds
2024-02-01 09:58:48,653 | DEBUG | recorder.audio_buffer | AudioBuffer initialized with buffer duration: 40 secs, sample rate: 32000
2024-02-01 09:58:48,654 | INFO | recorder.audio_segment_manager | Audio segment manager initialized.
2024-02-01 09:58:48,668 | INFO | recorder.audio_capture_processor | Audio stream opened successfully. Recording started.
2024-02-01 09:58:52,357 | DEBUG | asyncio | Using proactor: IocpProactor
2024-02-01 09:59:06,954 | INFO | utils.utils | 


Starting main program...
2024-02-01 09:59:06,954 | DEBUG | utils.utils | Beginning to clear recordings from directory: backend\data\recordings
2024-02-01 09:59:06,955 | INFO | utils.utils | There were no files to delete from 'backend\data\recordings' directory.
2024-02-01 09:59:06,961 | DEBUG | root | Audio Stream Processor initialized | Sample Rate: 32000, Chunk Duration = 0.5 seconds
2024-02-01 09:59:06,962 | DEBUG | recorder.audio_buffer | AudioBuffer initialized with buffer duration: 40 secs, sample rate: 32000
2024-02-01 09:59:06,962 | INFO | recorder.audio_segment_manager | Audio segment manager initialized.
2024-02-01 09:59:06,976 | INFO | recorder.audio_capture_processor | Audio stream opened successfully. Recording started.
2024-02-01 09:59:10,827 | DEBUG | asyncio | Using proactor: IocpProactor
2024-02-01 09:59:53,685 | ERROR | __mp_main__ | Error occurred in transcription worker: [WinError 6] The handle is invalid
Traceback (most recent call last):
  File "C:\Users\hello\coding\full_stack_apps\advanced_ai_call_assistant\backend\main.py", line 25, in transcription_worker
    transcriber.load_model()
  File "C:\Users\hello\coding\full_stack_apps\advanced_ai_call_assistant\backend\transcriber\transcriber_service.py", line 37, in load_model
    self.whisper_model = WhisperModelLoader.load_model(MODEL_NAME)
  File "C:\Users\hello\coding\full_stack_apps\advanced_ai_call_assistant\backend\utils\load_model.py", line 18, in load_model
    whisper_model = whisper.load_model("base")
  File "C:\Users\hello\miniconda3\envs\advanced_ai_call_assistant\lib\site-packages\whisper\__init__.py", line 133, in load_model
    checkpoint_file = _download(_MODELS[name], download_root, in_memory)
  File "C:\Users\hello\miniconda3\envs\advanced_ai_call_assistant\lib\site-packages\whisper\__init__.py", line 70, in _download
    with tqdm(
  File "C:\Users\hello\miniconda3\envs\advanced_ai_call_assistant\lib\site-packages\tqdm\std.py", line 1099, in __init__
    self.refresh(lock_args=self.lock_args)
  File "C:\Users\hello\miniconda3\envs\advanced_ai_call_assistant\lib\site-packages\tqdm\std.py", line 1348, in refresh
    self.display()
  File "C:\Users\hello\miniconda3\envs\advanced_ai_call_assistant\lib\site-packages\tqdm\std.py", line 1496, in display
    self.sp(self.__str__() if msg is None else msg)
  File "C:\Users\hello\miniconda3\envs\advanced_ai_call_assistant\lib\site-packages\tqdm\std.py", line 462, in print_status
    fp_write('\r' + s + (' ' * max(last_len[0] - len_s, 0)))
  File "C:\Users\hello\miniconda3\envs\advanced_ai_call_assistant\lib\site-packages\tqdm\std.py", line 455, in fp_write
    fp.write(str(s))
  File "C:\Users\hello\miniconda3\envs\advanced_ai_call_assistant\lib\site-packages\tqdm\utils.py", line 195, in inner
    return func(*args, **kwargs)
  File "c:\Users\hello\.vscode\extensions\ms-python.python-2023.22.1\pythonFiles\lib\python\debugpy\_vendored\pydevd\_pydevd_bundle\pydevd_io.py", line 40, in write
    r.write(s)
OSError: [WinError 6] The handle is invalid
2024-02-01 10:04:53,222 | INFO | utils.utils | 


Starting main program...
2024-02-01 10:04:53,223 | DEBUG | utils.utils | Beginning to clear recordings from directory: backend\data\recordings
2024-02-01 10:04:53,223 | INFO | utils.utils | There were no files to delete from 'backend\data\recordings' directory.
2024-02-01 10:04:53,230 | DEBUG | root | Audio Stream Processor initialized | Sample Rate: 32000, Chunk Duration = 0.5 seconds
2024-02-01 10:04:53,230 | DEBUG | recorder.audio_buffer | AudioBuffer initialized with buffer duration: 40 secs, sample rate: 32000
2024-02-01 10:04:53,231 | INFO | recorder.audio_segment_manager | Audio segment manager initialized.
2024-02-01 10:04:53,248 | INFO | recorder.audio_capture_processor | Audio stream opened successfully. Recording started.
2024-02-01 10:04:57,094 | DEBUG | asyncio | Using proactor: IocpProactor
2024-02-01 10:06:01,936 | ERROR | __mp_main__ | Error occurred in transcription worker: [WinError 6] The handle is invalid
Traceback (most recent call last):
  File "C:\Users\hello\coding\full_stack_apps\advanced_ai_call_assistant\backend\main.py", line 25, in transcription_worker
    transcriber.load_model()
  File "C:\Users\hello\coding\full_stack_apps\advanced_ai_call_assistant\backend\transcriber\transcriber_service.py", line 37, in load_model
    self.whisper_model = WhisperModelLoader.load_model(MODEL_NAME)
  File "C:\Users\hello\coding\full_stack_apps\advanced_ai_call_assistant\backend\utils\load_model.py", line 18, in load_model
    whisper_model = whisper.load_model("base")
  File "C:\Users\hello\miniconda3\envs\advanced_ai_call_assistant\lib\site-packages\whisper\__init__.py", line 133, in load_model
    checkpoint_file = _download(_MODELS[name], download_root, in_memory)
  File "C:\Users\hello\miniconda3\envs\advanced_ai_call_assistant\lib\site-packages\whisper\__init__.py", line 70, in _download
    with tqdm(
  File "C:\Users\hello\miniconda3\envs\advanced_ai_call_assistant\lib\site-packages\tqdm\std.py", line 1099, in __init__
    self.refresh(lock_args=self.lock_args)
  File "C:\Users\hello\miniconda3\envs\advanced_ai_call_assistant\lib\site-packages\tqdm\std.py", line 1348, in refresh
    self.display()
  File "C:\Users\hello\miniconda3\envs\advanced_ai_call_assistant\lib\site-packages\tqdm\std.py", line 1496, in display
    self.sp(self.__str__() if msg is None else msg)
  File "C:\Users\hello\miniconda3\envs\advanced_ai_call_assistant\lib\site-packages\tqdm\std.py", line 462, in print_status
    fp_write('\r' + s + (' ' * max(last_len[0] - len_s, 0)))
  File "C:\Users\hello\miniconda3\envs\advanced_ai_call_assistant\lib\site-packages\tqdm\std.py", line 455, in fp_write
    fp.write(str(s))
  File "C:\Users\hello\miniconda3\envs\advanced_ai_call_assistant\lib\site-packages\tqdm\utils.py", line 195, in inner
    return func(*args, **kwargs)
  File "c:\Users\hello\.vscode\extensions\ms-python.python-2023.22.1\pythonFiles\lib\python\debugpy\_vendored\pydevd\_pydevd_bundle\pydevd_io.py", line 40, in write
    r.write(s)
OSError: [WinError 6] The handle is invalid
2024-02-01 10:22:59,562 | INFO | utils.utils | 


Starting main program...
2024-02-01 10:22:59,562 | DEBUG | utils.utils | Beginning to clear recordings from directory: backend\data\recordings
2024-02-01 10:22:59,562 | INFO | utils.utils | There were no files to delete from 'backend\data\recordings' directory.
2024-02-01 10:22:59,565 | DEBUG | root | Audio Stream Processor initialized | Sample Rate: 32000, Chunk Duration = 0.5 seconds
2024-02-01 10:22:59,565 | DEBUG | recorder.audio_buffer | AudioBuffer initialized with buffer duration: 40 secs, sample rate: 32000
2024-02-01 10:22:59,565 | INFO | recorder.audio_segment_manager | Audio segment manager initialized.
2024-02-01 10:22:59,581 | INFO | recorder.audio_capture_processor | Audio stream opened successfully. Recording started.
2024-02-01 10:23:02,039 | DEBUG | asyncio | Using proactor: IocpProactor
2024-02-01 10:23:44,866 | ERROR | __mp_main__ | Error occurred in transcription worker: [WinError 6] The handle is invalid
Traceback (most recent call last):
  File "c:\Users\hello\coding\full_stack_apps\advanced_ai_call_assistant\backend\main.py", line 25, in transcription_worker
    transcriber.load_model()
  File "c:\Users\hello\coding\full_stack_apps\advanced_ai_call_assistant\backend\transcriber\transcriber_service.py", line 37, in load_model
    self.whisper_model = WhisperModelLoader.load_model(MODEL_NAME)
  File "c:\Users\hello\coding\full_stack_apps\advanced_ai_call_assistant\backend\utils\load_model.py", line 18, in load_model
    whisper_model = whisper.load_model("base")
  File "C:\Users\hello\miniconda3\envs\advanced_ai_call_assistant\lib\site-packages\whisper\__init__.py", line 133, in load_model
    checkpoint_file = _download(_MODELS[name], download_root, in_memory)
  File "C:\Users\hello\miniconda3\envs\advanced_ai_call_assistant\lib\site-packages\whisper\__init__.py", line 70, in _download
    with tqdm(
  File "C:\Users\hello\miniconda3\envs\advanced_ai_call_assistant\lib\site-packages\tqdm\std.py", line 1097, in __init__
    self.sp = self.status_printer(self.fp)
  File "C:\Users\hello\miniconda3\envs\advanced_ai_call_assistant\lib\site-packages\tqdm\std.py", line 451, in status_printer
    getattr(sys.stderr, 'flush', lambda: None)()
OSError: [WinError 6] The handle is invalid
2024-02-01 10:42:26,518 | INFO | utils.utils | 


Starting main program...
2024-02-01 10:42:26,519 | DEBUG | utils.utils | Beginning to clear recordings from directory: backend\data\recordings
2024-02-01 10:42:26,519 | INFO | utils.utils | There were no files to delete from 'backend\data\recordings' directory.
2024-02-01 10:42:26,527 | DEBUG | root | Audio Stream Processor initialized | Sample Rate: 32000, Chunk Duration = 0.5 seconds
2024-02-01 10:42:26,527 | DEBUG | recorder.audio_buffer | AudioBuffer initialized with buffer duration: 40 secs, sample rate: 32000
2024-02-01 10:42:26,528 | INFO | recorder.audio_segment_manager | Audio segment manager initialized.
2024-02-01 10:42:26,541 | INFO | recorder.audio_capture_processor | Audio stream opened successfully. Recording started.
2024-02-01 10:42:30,431 | DEBUG | asyncio | Using proactor: IocpProactor
2024-02-01 10:43:13,247 | ERROR | __mp_main__ | Error occurred in transcription worker: [WinError 6] The handle is invalid
Traceback (most recent call last):
  File "C:\Users\hello\coding\full_stack_apps\advanced_ai_call_assistant\backend\main.py", line 25, in transcription_worker
    transcriber.load_model()
  File "C:\Users\hello\coding\full_stack_apps\advanced_ai_call_assistant\backend\transcriber\transcriber_service.py", line 37, in load_model
    self.whisper_model = WhisperModelLoader.load_model(MODEL_NAME)
  File "C:\Users\hello\coding\full_stack_apps\advanced_ai_call_assistant\backend\utils\load_model.py", line 18, in load_model
    whisper_model = whisper.load_model("base")
  File "C:\Users\hello\miniconda3\envs\advanced_ai_call_assistant\lib\site-packages\whisper\__init__.py", line 133, in load_model
    checkpoint_file = _download(_MODELS[name], download_root, in_memory)
  File "C:\Users\hello\miniconda3\envs\advanced_ai_call_assistant\lib\site-packages\whisper\__init__.py", line 70, in _download
    with tqdm(
  File "C:\Users\hello\miniconda3\envs\advanced_ai_call_assistant\lib\site-packages\tqdm\std.py", line 1099, in __init__
    self.refresh(lock_args=self.lock_args)
  File "C:\Users\hello\miniconda3\envs\advanced_ai_call_assistant\lib\site-packages\tqdm\std.py", line 1348, in refresh
    self.display()
  File "C:\Users\hello\miniconda3\envs\advanced_ai_call_assistant\lib\site-packages\tqdm\std.py", line 1496, in display
    self.sp(self.__str__() if msg is None else msg)
  File "C:\Users\hello\miniconda3\envs\advanced_ai_call_assistant\lib\site-packages\tqdm\std.py", line 462, in print_status
    fp_write('\r' + s + (' ' * max(last_len[0] - len_s, 0)))
  File "C:\Users\hello\miniconda3\envs\advanced_ai_call_assistant\lib\site-packages\tqdm\std.py", line 455, in fp_write
    fp.write(str(s))
  File "C:\Users\hello\miniconda3\envs\advanced_ai_call_assistant\lib\site-packages\tqdm\utils.py", line 195, in inner
    return func(*args, **kwargs)
  File "c:\Users\hello\.vscode\extensions\ms-python.python-2023.22.1\pythonFiles\lib\python\debugpy\_vendored\pydevd\_pydevd_bundle\pydevd_io.py", line 40, in write
    r.write(s)
OSError: [WinError 6] The handle is invalid
